<?xml version="1.0"?>
<sdf version="1.5">
    <model name="revolute2_demo">
        <link name="heavy_base">
            <!-- position the base such that the bottom touches the floor -->
            <pose>0 0 0.05 0 0 0</pose>
            <inertial>
                <mass>100</mass>                <!-- kg -->
                <inertia>
                    <!-- (mass / 12) * (y*y + z*z) -->
                    <ixx>8.4167</ixx>
                    <ixy>0</ixy>
                    <ixz>0</ixz>
                    <!-- (mass / 12) * (x*x + z*z) -->
                    <iyy>40.417</iyy>
                    <iyz>0</iyz>
                    <!-- (mass / 12) * (y*y + x*x) -->
                    <izz>48.667</izz>
                </inertia>
            </inertial>
            <!-- Same geometry as visual -->
            <collision name="heavy_base_collision">
                <geometry>
                    <box>
                        <size>2.2 1 0.1</size>
                    </box>
                </geometry>
            </collision>
            <!-- Same geometry as collision -->
            <visual name="heavy_base_visual">
                <geometry>
                    <box>
                        <size>2.2 1 0.1</size>
                    </box>
                </geometry>
                <material>
                    <script>
                        <uri>model://demo_joint_types/materials/scripts</uri>
                        <uri>model://demo_joint_types/materials/textures</uri>
                        <name>demo_joint_types/legend</name>
                    </script>
                </material>
            </visual>
        </link>

        <link name="universal_base">
            <!-- make the base float in the sky -->
            <pose >0.9 0 0.55 0 0 0</pose>
            <inertial>
                <inertia>
                    <!-- (mass / 12) * (y*y + z*z) -->
                    <ixx>0.0016667</ixx>
                    <ixy>0</ixy>
                    <ixz>0</ixz>
                    <!-- (mass / 12) * (x*x + z*z) -->
                    <iyy>0.0016667</iyy>
                    <iyz>0</iyz>
                    <!-- (mass / 12) * (y*y + x*x) -->
                    <izz>0.0016667</izz>
                </inertia>
            </inertial>
            <!-- Same geometry as visual -->
            <collision name="universal_base_collision">
                <geometry>
                    <box>
                        <size>0.1 0.1 0.1</size>
                    </box>
                </geometry>
            </collision>
            <!-- Same geometry as collision -->
            <visual name="universal_base_visual">
                <geometry>
                    <box>
                        <size>0.1 0.1 0.1</size>
                    </box>
                </geometry>
                <material>
                    <script>
                        <uri>model://demo_joint_types/materials/scripts</uri>
                        <uri>model://demo_joint_types/materials/textures</uri>
                        <name>demo_joint_types/parent</name>
                    </script>
                </material>
            </visual>
        </link>

        <joint name="universal_base_to_heavy_base" type="fixed">
            <parent>heavy_base</parent>
            <child>universal_base</child>
        </joint>

        <link name="universal_shaft">
            <!-- Put the shaft just under the base -->
            <pose >0.9 -0.075 0.44 1.5708 0 0</pose>
            <inertial>
                <inertia>
                    <!-- (mass / 12) * (3 * radius * radius + length * length) -->
                    <ixx>0.0058333</ixx>
                    <ixy>0</ixy>
                    <ixz>0</ixz>
                    <!-- (mass / 12) * (3 * radius * radius + length * length) -->
                    <iyy>0.0058333</iyy>
                    <iyz>0</iyz>
                    <!-- mass * radius * radius * 0.5 -->
                    <izz>0.00125</izz>
                </inertia>
                <!-- offset interia as a trick to get movement from gravity -->
                <pose >-0.02 0.02 0 0 0 0</pose>
            </inertial>
            <!-- Same geometry as visual -->
            <collision name="universal_shaft_collision">
                <geometry>
                    <cylinder>
                        <radius>0.05</radius>
                        <length>0.25</length>
                    </cylinder>
                </geometry>
            </collision>
            <!-- Same geometry as collision -->
            <visual name="universal_shaft_visual">
                <geometry>
                    <cylinder>
                        <radius>0.05</radius>
                        <length>0.25</length>
                    </cylinder>
                </geometry>
                <material>
                    <script>
                        <uri>model://demo_joint_types/materials/scripts</uri>
                        <uri>model://demo_joint_types/materials/textures</uri>
                        <name>demo_joint_types/child</name>
                    </script>
                </material>
            </visual>
        </link>

        <joint name="universal_demo" type="universal">
            <parent>universal_base</parent>
            <child>universal_shaft</child>
            <pose>0 0 -0.075 0 0 0</pose>
        </joint>
    </model>
</sdf>