<?xml version="1.0"?>
<sdf version="1.5">
    <model name="revolute2_demo">
        <link name="heavy_base">
            <!-- position the base such that the bottom touches the floor -->
            <pose>0 0 0.05 0 0 0</pose>
            <inertial>
                <mass>100</mass>                <!-- kg -->
                <inertia>
                    <!-- (mass / 12) * (y*y + z*z) -->
                    <ixx>8.4167</ixx>
                    <ixy>0</ixy>
                    <ixz>0</ixz>
                    <!-- (mass / 12) * (x*x + z*z) -->
                    <iyy>40.417</iyy>
                    <iyz>0</iyz>
                    <!-- (mass / 12) * (y*y + x*x) -->
                    <izz>48.667</izz>
                </inertia>
            </inertial>
            <!-- Same geometry as visual -->
            <collision name="heavy_base_collision">
                <geometry>
                    <box>
                        <size>2.2 1 0.1</size>
                    </box>
                </geometry>
            </collision>
            <!-- Same geometry as collision -->
            <visual name="heavy_base_visual">
                <geometry>
                    <box>
                        <size>2.2 1 0.1</size>
                    </box>
                </geometry>
                <material>
                    <script>
                        <uri>model://demo_joint_types/materials/scripts</uri>
                        <uri>model://demo_joint_types/materials/textures</uri>
                        <name>demo_joint_types/legend</name>
                    </script>
                </material>
            </visual>
        </link>

        <link name="revolute2_base">
            <!-- Put the bottom of the child on top of the parent-->
            <pose >-.17 0 0.35 0 0 0</pose>
            <inertial>
                <inertia>
                    <!-- (mass / 12) * (y*y + z*z) -->
                    <ixx>0.021667</ixx>
                    <ixy>0</ixy>
                    <ixz>0</ixz>
                    <!-- (mass / 12) * (x*x + z*z) -->
                    <iyy>0.021667</iyy>
                    <iyz>0</iyz>
                    <!-- (mass / 12) * (y*y + x*x) -->
                    <izz>0.0016667</izz>
                </inertia>
            </inertial>
            <!-- Same geometry as visual -->
            <collision name="revolute2_base_collision">
                <geometry>
                    <box>
                        <size>0.1 0.1 0.5</size>
                    </box>
                </geometry>
            </collision>
            <!-- Same geometry as collision -->
            <visual name="revolute2_base_visual">
                <geometry>
                    <box>
                        <size>0.1 0.1 0.5</size>
                    </box>
                </geometry>
                <material>
                    <script>
                        <uri>model://demo_joint_types/materials/scripts</uri>
                        <uri>model://demo_joint_types/materials/textures</uri>
                        <name>demo_joint_types/parent</name>
                    </script>
                </material>
            </visual>
        </link>

        <joint name="revolute2_base_to_heavy_base" type="fixed">
            <parent>heavy_base</parent>
            <child>revolute2_base</child>
        </joint>

        <link name="revolute2_arm">
            <!-- Put the arm near the top of the base
             -->
            <pose >-.06 -0.075 0.55 1.5708 0 0</pose>
            <inertial>
                <inertia>
                    <!-- (mass / 12) * (3 * radius * radius + length * length) -->
                    <ixx>0.0058333</ixx>
                    <ixy>0</ixy>
                    <ixz>0</ixz>
                    <!-- (mass / 12) * (3 * radius * radius + length * length) -->
                    <iyy>0.0058333</iyy>
                    <iyz>0</iyz>
                    <!-- mass * radius * radius * 0.5 -->
                    <izz>0.00125</izz>
                </inertia>
                <!-- offset interia as a trick to get movement from gravity -->
                <pose >-.1 -0.1 0.1 0 0 0</pose>
            </inertial>
            <!-- Same geometry as visual -->
            <collision name="revolute2_arm_collision">
                <geometry>
                    <cylinder>
                        <radius>0.05</radius>
                        <length>0.25</length>
                    </cylinder>
                </geometry>
            </collision>
            <!-- Same geometry as collision -->
            <visual name="revolute2_arm_visual">
                <geometry>
                    <cylinder>
                        <radius>0.05</radius>
                        <length>0.25</length>
                    </cylinder>
                </geometry>
                <material>
                    <script>
                        <uri>model://demo_joint_types/materials/scripts</uri>
                        <uri>model://demo_joint_types/materials/textures</uri>
                        <name>demo_joint_types/child</name>
                    </script>
                </material>
            </visual>
        </link>

        <joint name="revolute2_demo" type="revolute2">
            <parent>revolute2_base</parent>
            <child>revolute2_arm</child>
            <axis>
                <xyz>1 0 0</xyz>
            </axis>
            <axis2>
                <xyz>0 1 0</xyz>
            </axis2>
            <pose>0 0 -0.075  0 0 0</pose>
        </joint>
    </model>
</sdf>