<?xml version="1.0" ?>
<!-- =================================================================================== -->
<!-- |    This document was autogenerated by xacro from /home/user/dev_ws/src/skbot/skbot_description/sdf/hung/model.sdf.xacro | -->
<!-- |    EDITING THIS FILE BY HAND IS NOT RECOMMENDED                                 | -->
<!-- =================================================================================== -->
<sdf version="1.5">
  <model name="hung">
    <!-- base -->
    <link name="base">
      <pose>0 0 0.25 0 0 0</pose>
      <collision name="base_collision">
        <geometry>
          <box>
            <size>10 10 0.5</size>
          </box>
        </geometry>
      </collision>
      <visual name="base_visual">
        <geometry>
          <box>
            <size>10 10 0.5</size>
          </box>
        </geometry>
      </visual>
      <inertial>
        <inertia>
          <ixx>835.4166666666666</ixx>
          <ixy>0</ixy>
          <ixz>0</ixz>
          <iyy>835.4166666666666</iyy>
          <iyz>0</iyz>
          <izz>835.4166666666666</izz>
        </inertia>
        <mass>100</mass>
      </inertial>
    </link>
    <!-- poll -->
    <link name="poll">
      <pose frame="base">0 0 5.0 0 0 0</pose>
      <collision name="base_collision">
        <geometry>
          <box>
            <size>1 1 10</size>
          </box>
        </geometry>
      </collision>
      <visual name="base_visual">
        <geometry>
          <box>
            <size>1 1 10</size>
          </box>
        </geometry>
      </visual>
      <inertial>
        <inertia>
          <ixx>841.6666666666666</ixx>
          <ixy>0</ixy>
          <ixz>0</ixz>
          <iyy>841.6666666666666</iyy>
          <iyz>0</iyz>
          <izz>841.6666666666666</izz>
        </inertia>
        <mass>100</mass>
      </inertial>
    </link>
    <joint name="base2poll" type="fixed">
      <parent>base</parent>
      <child>poll</child>
    </joint>
    <!-- arm -->
    <link name="arm">
      <pose frame="poll">2.0 0 5.5 0 1.57 0</pose>
      <collision name="arm_collision">
        <geometry>
          <box>
            <size>1 1 5</size>
          </box>
        </geometry>
      </collision>
      <visual name="arm_visual">
        <geometry>
          <box>
            <size>1 1 5</size>
          </box>
        </geometry>
      </visual>
      <inertial>
        <inertia>
          <ixx>21.666666666666668</ixx>
          <ixy>0</ixy>
          <ixz>0</ixz>
          <iyy>21.666666666666668</iyy>
          <iyz>0</iyz>
          <izz>21.666666666666668</izz>
        </inertia>
        <mass>10</mass>
      </inertial>
    </link>
    <joint name="arm2hose" type="fixed">
      <parent>poll</parent>
      <child>arm</child>
    </joint>
    <include>
      <pose frame="arm">0.5 0 2.5 -1.5707 0 0</pose>
      <uri>model://fire_hose_long</uri>
    </include>
    <joint name="arm2poll" type="fixed">
      <parent>arm</parent>
      <child>fire_hose_long::nozzle</child>
    </joint>
    <!-- simple_box -->
    <link name="simple_box">
      <pose frame="fire_hose_long::coupling">0.45 0 0 0 0 0</pose>
      <collision name="simple_box_collision">
        <geometry>
          <box>
            <size>0.5 0.5 0.5</size>
          </box>
        </geometry>
      </collision>
      <visual name="simple_box_visual">
        <geometry>
          <box>
            <size>0.5 0.5 0.5</size>
          </box>
        </geometry>
      </visual>
      <inertial>
        <inertia>
          <ixx>0.125</ixx>
          <ixy>0</ixy>
          <ixz>0</ixz>
          <iyy>0.125</iyy>
          <iyz>0</iyz>
          <izz>0.125</izz>
        </inertia>
        <mass>3</mass>
      </inertial>
    </link>
    <joint name="hose2simple_box" type="universal">
      <pose>-0.25 0 0 0 0 0</pose>
      <parent>fire_hose_long::coupling</parent>
      <child>simple_box</child>
    </joint>
  </model>
</sdf>
